ERROR > An Error Occured.
Traceback (most recent call last):
  File "C:\Users\User\AppData\Local\Programs\Python\Python38-32\lib\site-packages\discord\ext\commands\bot.py", line 596, in _load_from_module_spec
    spec.loader.exec_module(lib)
  File "<frozen importlib._bootstrap_external>", line 779, in exec_module
  File "<frozen importlib._bootstrap_external>", line 916, in get_code
  File "<frozen importlib._bootstrap_external>", line 846, in source_to_code
  File "<frozen importlib._bootstrap>", line 219, in _call_with_frames_removed
  File "c:\Users\User\Desktop\Bot Maker Items\Bot\Bot-Python\commands\userinfo.py", line 14
    if fvalue < 7 Days:
                  ^
SyntaxError: invalid syntax

The above exception was the direct cause of the following exception:

Traceback (most recent call last):
  File "c:/Users/User/Desktop/Bot Maker Items/Bot/Bot-Python/d.py", line 34, in <module>
    bot.load_extension(cog)
  File "C:\Users\User\AppData\Local\Programs\Python\Python38-32\lib\site-packages\discord\ext\commands\bot.py", line 653, in load_extension
    self._load_from_module_spec(spec, name)
  File "C:\Users\User\AppData\Local\Programs\Python\Python38-32\lib\site-packages\discord\ext\commands\bot.py", line 599, in _load_from_module_spec
    raise errors.ExtensionFailed(key, e) from e
discord.ext.commands.errors.ExtensionFailed: Extension 'commands.userinfo' raised an error: SyntaxError: invalid syntax (userinfo.py, line 14)
